<?xml version="1.0" ?>
<sdf version="1.9">
  <world name="lane_world">
    
    <plugin filename="gz-sim-physics-system" name="gz::sim::systems::Physics"/>
    <plugin filename="gz-sim-sensors-system" name="gz::sim::systems::Sensors">
      <render_engine>ogre2</render_engine>
    </plugin>
    <plugin filename="gz-sim-scene-broadcaster-system" name="gz::sim::systems::SceneBroadcaster"/>
    <plugin filename="gz-sim-user-commands-system" name="gz::sim::systems::UserCommands"/>

    <physics type="ode">
      <max_step_size>0.004</max_step_size>
      <real_time_update_rate>250</real_time_update_rate>
    </physics>

    <scene>
      <shadows>false</shadows>
    </scene>

    <include>
      <uri>https://fuel.gazebosim.org/1.0/OpenRobotics/models/Sun</uri>
    </include>

    <model name="ground_plane">
      <static>true</static>
      <link name="link">
        <collision name="collision">
          <geometry><plane><normal>0 0 1</normal><size>50 50</size></plane></geometry>
        </collision>
        <visual name="visual">
          <geometry><plane><normal>0 0 1</normal><size>50 50</size></plane></geometry>
          <material><ambient>0.8 0.8 0.8 1</ambient><diffuse>0.8 0.8 0.8 1</diffuse></material>
        </visual>
      </link>
    </model>

    <model name="left_lane">
      <static>true</static>
      <pose>0 0.225 0.01 0 0 0</pose>
      <link name="link">
        <visual name="visual">
          <geometry><box><size>10 0.05 0.01</size></box></geometry>
          <material><ambient>1 0 0 1</ambient><diffuse>1 0 0 1</diffuse></material>
        </visual>
      </link>
    </model>

    <model name="right_lane">
      <static>true</static>
      <pose>0 -0.225 0.01 0 0 0</pose>
      <link name="link">
        <visual name="visual">
          <geometry><box><size>10 0.05 0.01</size></box></geometry>
          <material><ambient>1 0 0 1</ambient><diffuse>1 0 0 1</diffuse></material>
        </visual>
      </link>
    </model>
<model name="my_robot">
      <pose>-5 0 0.2 0 0 0</pose> <link name="base_link">
        <inertial>
          <mass>1.5</mass>
          <inertia>
            <ixx>0.01</ixx><iyy>0.01</iyy><izz>0.01</izz>
          </inertia>
        </inertial>
        <visual name="visual">
          <geometry><box><size>0.4 0.2 0.08</size></box></geometry> <material><ambient>0 0 1 1</ambient><diffuse>0 0 1 1</diffuse></material>
        </visual>
        <collision name="collision">
          <geometry><box><size>0.4 0.2 0.08</size></box></geometry>
        </collision>
      </link>

      <link name="left_wheel">
        <pose>0.1 0.13 -0.05 -1.5707 0 0</pose>
        <inertial> <mass>0.5</mass>
          <inertia>
            <ixx>0.001</ixx><iyy>0.001</iyy><izz>0.001</izz>
          </inertia>
        </inertial>
        <collision name="collision">
          <geometry><cylinder><radius>0.05</radius><length>0.04</length></cylinder></geometry>
        </collision>
        <visual name="visual">
          <geometry><cylinder><radius>0.05</radius><length>0.04</length></cylinder></geometry>
          <material><ambient>0 0 0 1</ambient><diffuse>0 0 0 1</diffuse></material>
        </visual>
      </link>

      <link name="right_wheel">
        <pose>0.1 -0.13 -0.05 -1.5707 0 0</pose>
        <inertial> <mass>0.5</mass>
          <inertia>
            <ixx>0.001</ixx><iyy>0.001</iyy><izz>0.001</izz>
          </inertia>
        </inertial>
        <collision name="collision">
          <geometry><cylinder><radius>0.05</radius><length>0.04</length></cylinder></geometry>
        </collision>
        <visual name="visual">
          <geometry><cylinder><radius>0.05</radius><length>0.04</length></cylinder></geometry>
          <material><ambient>0 0 0 1</ambient><diffuse>0 0 0 1</diffuse></material>
        </visual>
      </link>

      <link name="caster">
        <pose>-0.15 0 -0.075 0 0 0</pose>
        <inertial>
          <mass>0.1</mass>
          <inertia>
            <ixx>0.0001</ixx><iyy>0.0001</iyy><izz>0.0001</izz>
          </inertia>
        </inertial>
        <collision name="collision">
          <geometry><sphere><radius>0.025</radius></sphere></geometry>
          <surface>
            <friction>
              <ode><mu>0.1</mu><mu2>0.1</mu2></ode>
            </friction>
          </surface>
        </collision>
      </link>

      <joint name="left_wheel_joint" type="revolute">
        <parent>base_link</parent>
        <child>left_wheel</child>
        <axis>
          <xyz>0 0 1</xyz> </axis>
      </joint>

      <joint name="right_wheel_joint" type="revolute">
        <parent>base_link</parent>
        <child>right_wheel</child>
        <axis>
          <xyz>0 0 1</xyz>
        </axis>
      </joint>

      <joint name="caster_joint" type="ball">
        <parent>base_link</parent>
        <child>caster</child>
      </joint>

      <link name="lidar_link">
        <pose>0.15 0 0.08 0 0 0</pose>
        <visual name="visual">
          <geometry><cylinder><radius>0.03</radius><length>0.05</length></cylinder></geometry>
          <material><ambient>1 0 0 1</ambient><diffuse>1 0 0 1</diffuse></material>
        </visual>
        <sensor name="gpu_lidar" type="gpu_lidar">
          <topic>scan</topic>
          <update_rate>10</update_rate>
          <ray>
            <scan>
              <horizontal><samples>360</samples><min_angle>-3.14</min_angle><max_angle>3.14</max_angle></horizontal>
            </scan>
            <range><min>0.1</min><max>10.0</max></range>
          </ray>
          <gz_frame_id>lidar_link</gz_frame_id>
        </sensor>
      </link>

      <joint name="lidar_joint" type="fixed">
        <parent>base_link</parent>
        <child>lidar_link</child>
      </joint>

      <plugin filename="gz-sim-diff-drive-system" name="gz::sim::systems::DiffDrive">
        <left_joint>left_wheel_joint</left_joint>
        <right_joint>right_wheel_joint</right_joint>
        <wheel_separation>0.26</wheel_separation>
        <wheel_radius>0.05</wheel_radius>
        <topic>cmd_vel</topic>
        <odom_topic>odom</odom_topic>
        <tf_topic>/tf</tf_topic>
      </plugin>
<link name="camera_link">
  <pose>0.2 0 0.05 0 0 0</pose> <visual name="visual">
    <geometry><box><size>0.02 0.05 0.02</size></box></geometry>
    <material><ambient>0 0 0 1</ambient><diffuse>0 0 0 1</diffuse></material>
  </visual>
  <sensor name="camera" type="camera">
    <pose>0 0 0 0 0 0</pose>
    <visualize>true</visualize>
    <update_rate>30</update_rate>
    <topic>camera/image_raw</topic>
    <gz_frame_id>camera_link</gz_frame_id>
    <camera>
      <horizontal_fov>1.089</horizontal_fov>
      <image>
        <width>640</width>
        <height>480</height>
        <format>R8G8B8</format>
      </image>
      <clip>
        <near>0.05</near>
        <far>100</far>
      </clip>
    </camera>
  </sensor>
</link>

<joint name="camera_joint" type="fixed">
  <parent>base_link</parent>
  <child>camera_link</child>
</joint>
    </model>
    
  </world>
</sdf>
